2025-06-03 17:43:22,532 INFO    MainThread:25396 [wandb_setup.py:_flush():70] Current SDK version is 0.19.11
2025-06-03 17:43:22,532 INFO    MainThread:25396 [wandb_setup.py:_flush():70] Configure stats pid to 25396
2025-06-03 17:43:22,532 INFO    MainThread:25396 [wandb_setup.py:_flush():70] Loading settings from C:\Users\HEEKWON\.config\wandb\settings
2025-06-03 17:43:22,532 INFO    MainThread:25396 [wandb_setup.py:_flush():70] Loading settings from D:\Projects\Python\ReinforcementLearning\project_2\pongGame\wandb\settings
2025-06-03 17:43:22,532 INFO    MainThread:25396 [wandb_setup.py:_flush():70] Loading settings from environment variables
2025-06-03 17:43:22,533 INFO    MainThread:25396 [wandb_init.py:setup_run_log_directory():724] Logging user logs to D:\Projects\Python\ReinforcementLearning\project_2\pongGame\wandb\run-20250603_174322-qh8p19lw\logs\debug.log
2025-06-03 17:43:22,533 INFO    MainThread:25396 [wandb_init.py:setup_run_log_directory():725] Logging internal logs to D:\Projects\Python\ReinforcementLearning\project_2\pongGame\wandb\run-20250603_174322-qh8p19lw\logs\debug-internal.log
2025-06-03 17:43:22,533 INFO    MainThread:25396 [wandb_init.py:init():852] calling init triggers
2025-06-03 17:43:22,533 INFO    MainThread:25396 [wandb_init.py:init():857] wandb.init called with sweep_config: {}
config: {'game': 'ALE/Pong-v5', 'possible_actions': [0, 2, 3], 'starting_mem_len': 50000, 'max_mem_len': 750000, 'starting_epsilon': 0.1, 'learn_rate': 0.00025, 'gamma': 0.95, 'epsilon_decay': 9e-06, 'epsilon_min': 0.05, 'batch_size': 32, 'target_update_freq': 10000, 'save_freq': 50000, 'episodes': 200, '_wandb': {}}
2025-06-03 17:43:22,533 INFO    MainThread:25396 [wandb_init.py:init():893] starting backend
2025-06-03 17:43:22,533 INFO    MainThread:25396 [wandb_init.py:init():897] sending inform_init request
2025-06-03 17:43:22,546 INFO    MainThread:25396 [backend.py:_multiprocessing_setup():101] multiprocessing start_methods=spawn, using: spawn
2025-06-03 17:43:22,547 INFO    MainThread:25396 [wandb_init.py:init():907] backend started and connected
2025-06-03 17:43:22,547 INFO    MainThread:25396 [wandb_init.py:init():1005] updated telemetry
2025-06-03 17:43:22,701 INFO    MainThread:25396 [wandb_init.py:init():1029] communicating run to backend with 90.0 second timeout
2025-06-03 17:43:23,409 INFO    MainThread:25396 [wandb_init.py:init():1104] starting run threads in backend
2025-06-03 17:43:23,497 INFO    MainThread:25396 [wandb_run.py:_console_start():2573] atexit reg
2025-06-03 17:43:23,498 INFO    MainThread:25396 [wandb_run.py:_redirect():2421] redirect: wrap_raw
2025-06-03 17:43:23,498 INFO    MainThread:25396 [wandb_run.py:_redirect():2490] Wrapping output streams.
2025-06-03 17:43:23,498 INFO    MainThread:25396 [wandb_run.py:_redirect():2513] Redirects installed.
2025-06-03 17:43:23,500 INFO    MainThread:25396 [wandb_init.py:init():1150] run started, returning control to user process
2025-06-03 17:43:24,813 INFO    MsgRouterThr:25396 [mailbox.py:close():129] [no run ID] Closing mailbox, abandoning 1 handles.
2025-06-03 17:43:26,451 ERROR   MainThread:25396 [redirect.py:_on_write():664] [no run ID] error in stderr callback
Traceback (most recent call last):
  File "C:\Users\HEEKWON\anaconda3\envs\reinforcementLearningProject_2\lib\site-packages\wandb\sdk\lib\redirect.py", line 662, in _on_write
    cb(written_data)
  File "C:\Users\HEEKWON\anaconda3\envs\reinforcementLearningProject_2\lib\site-packages\wandb\sdk\wandb_run.py", line 2500, in <lambda>
    lambda data: self._console_raw_callback("stderr", data),
  File "C:\Users\HEEKWON\anaconda3\envs\reinforcementLearningProject_2\lib\site-packages\wandb\sdk\wandb_run.py", line 406, in wrapper
    return func(self, *args, **kwargs)
  File "C:\Users\HEEKWON\anaconda3\envs\reinforcementLearningProject_2\lib\site-packages\wandb\sdk\wandb_run.py", line 464, in wrapper_fn
    return func(self, *args, **kwargs)
  File "C:\Users\HEEKWON\anaconda3\envs\reinforcementLearningProject_2\lib\site-packages\wandb\sdk\wandb_run.py", line 1639, in _console_raw_callback
    self._backend.interface.publish_output_raw(name, data)
  File "C:\Users\HEEKWON\anaconda3\envs\reinforcementLearningProject_2\lib\site-packages\wandb\sdk\interface\interface.py", line 762, in publish_output_raw
    self._publish_output_raw(o)
  File "C:\Users\HEEKWON\anaconda3\envs\reinforcementLearningProject_2\lib\site-packages\wandb\sdk\interface\interface_shared.py", line 38, in _publish_output_raw
    self._publish(rec)
  File "C:\Users\HEEKWON\anaconda3\envs\reinforcementLearningProject_2\lib\site-packages\wandb\sdk\interface\interface_sock.py", line 39, in _publish
    self._sock_client.send_record_publish(record)
  File "C:\Users\HEEKWON\anaconda3\envs\reinforcementLearningProject_2\lib\site-packages\wandb\sdk\lib\sock_client.py", line 174, in send_record_publish
    self.send_server_request(server_req)
  File "C:\Users\HEEKWON\anaconda3\envs\reinforcementLearningProject_2\lib\site-packages\wandb\sdk\lib\sock_client.py", line 154, in send_server_request
    self._send_message(msg)
  File "C:\Users\HEEKWON\anaconda3\envs\reinforcementLearningProject_2\lib\site-packages\wandb\sdk\lib\sock_client.py", line 151, in _send_message
    self._sendall_with_error_handle(header + data)
  File "C:\Users\HEEKWON\anaconda3\envs\reinforcementLearningProject_2\lib\site-packages\wandb\sdk\lib\sock_client.py", line 130, in _sendall_with_error_handle
    sent = self._sock.send(data)
ConnectionAbortedError: [WinError 10053] 현재 연결은 사용자의 호스트 시스템의 소프트웨어의 의해 중단되었습니다
2025-06-03 17:43:26,454 ERROR   MainThread:25396 [redirect.py:_on_write():664] [no run ID] error in stderr callback
Traceback (most recent call last):
  File "C:\Users\HEEKWON\anaconda3\envs\reinforcementLearningProject_2\lib\site-packages\wandb\sdk\lib\redirect.py", line 662, in _on_write
    cb(written_data)
  File "C:\Users\HEEKWON\anaconda3\envs\reinforcementLearningProject_2\lib\site-packages\wandb\sdk\wandb_run.py", line 2500, in <lambda>
    lambda data: self._console_raw_callback("stderr", data),
  File "C:\Users\HEEKWON\anaconda3\envs\reinforcementLearningProject_2\lib\site-packages\wandb\sdk\wandb_run.py", line 406, in wrapper
    return func(self, *args, **kwargs)
  File "C:\Users\HEEKWON\anaconda3\envs\reinforcementLearningProject_2\lib\site-packages\wandb\sdk\wandb_run.py", line 464, in wrapper_fn
    return func(self, *args, **kwargs)
  File "C:\Users\HEEKWON\anaconda3\envs\reinforcementLearningProject_2\lib\site-packages\wandb\sdk\wandb_run.py", line 1639, in _console_raw_callback
    self._backend.interface.publish_output_raw(name, data)
  File "C:\Users\HEEKWON\anaconda3\envs\reinforcementLearningProject_2\lib\site-packages\wandb\sdk\interface\interface.py", line 762, in publish_output_raw
    self._publish_output_raw(o)
  File "C:\Users\HEEKWON\anaconda3\envs\reinforcementLearningProject_2\lib\site-packages\wandb\sdk\interface\interface_shared.py", line 38, in _publish_output_raw
    self._publish(rec)
  File "C:\Users\HEEKWON\anaconda3\envs\reinforcementLearningProject_2\lib\site-packages\wandb\sdk\interface\interface_sock.py", line 39, in _publish
    self._sock_client.send_record_publish(record)
  File "C:\Users\HEEKWON\anaconda3\envs\reinforcementLearningProject_2\lib\site-packages\wandb\sdk\lib\sock_client.py", line 174, in send_record_publish
    self.send_server_request(server_req)
  File "C:\Users\HEEKWON\anaconda3\envs\reinforcementLearningProject_2\lib\site-packages\wandb\sdk\lib\sock_client.py", line 154, in send_server_request
    self._send_message(msg)
  File "C:\Users\HEEKWON\anaconda3\envs\reinforcementLearningProject_2\lib\site-packages\wandb\sdk\lib\sock_client.py", line 151, in _send_message
    self._sendall_with_error_handle(header + data)
  File "C:\Users\HEEKWON\anaconda3\envs\reinforcementLearningProject_2\lib\site-packages\wandb\sdk\lib\sock_client.py", line 130, in _sendall_with_error_handle
    sent = self._sock.send(data)
ConnectionAbortedError: [WinError 10053] 현재 연결은 사용자의 호스트 시스템의 소프트웨어의 의해 중단되었습니다
2025-06-03 17:43:26,455 ERROR   MainThread:25396 [redirect.py:_on_write():664] [no run ID] error in stderr callback
Traceback (most recent call last):
  File "C:\Users\HEEKWON\anaconda3\envs\reinforcementLearningProject_2\lib\site-packages\wandb\sdk\lib\redirect.py", line 662, in _on_write
    cb(written_data)
  File "C:\Users\HEEKWON\anaconda3\envs\reinforcementLearningProject_2\lib\site-packages\wandb\sdk\wandb_run.py", line 2500, in <lambda>
    lambda data: self._console_raw_callback("stderr", data),
  File "C:\Users\HEEKWON\anaconda3\envs\reinforcementLearningProject_2\lib\site-packages\wandb\sdk\wandb_run.py", line 406, in wrapper
    return func(self, *args, **kwargs)
  File "C:\Users\HEEKWON\anaconda3\envs\reinforcementLearningProject_2\lib\site-packages\wandb\sdk\wandb_run.py", line 464, in wrapper_fn
    return func(self, *args, **kwargs)
  File "C:\Users\HEEKWON\anaconda3\envs\reinforcementLearningProject_2\lib\site-packages\wandb\sdk\wandb_run.py", line 1639, in _console_raw_callback
    self._backend.interface.publish_output_raw(name, data)
  File "C:\Users\HEEKWON\anaconda3\envs\reinforcementLearningProject_2\lib\site-packages\wandb\sdk\interface\interface.py", line 762, in publish_output_raw
    self._publish_output_raw(o)
  File "C:\Users\HEEKWON\anaconda3\envs\reinforcementLearningProject_2\lib\site-packages\wandb\sdk\interface\interface_shared.py", line 38, in _publish_output_raw
    self._publish(rec)
  File "C:\Users\HEEKWON\anaconda3\envs\reinforcementLearningProject_2\lib\site-packages\wandb\sdk\interface\interface_sock.py", line 39, in _publish
    self._sock_client.send_record_publish(record)
  File "C:\Users\HEEKWON\anaconda3\envs\reinforcementLearningProject_2\lib\site-packages\wandb\sdk\lib\sock_client.py", line 174, in send_record_publish
    self.send_server_request(server_req)
  File "C:\Users\HEEKWON\anaconda3\envs\reinforcementLearningProject_2\lib\site-packages\wandb\sdk\lib\sock_client.py", line 154, in send_server_request
    self._send_message(msg)
  File "C:\Users\HEEKWON\anaconda3\envs\reinforcementLearningProject_2\lib\site-packages\wandb\sdk\lib\sock_client.py", line 151, in _send_message
    self._sendall_with_error_handle(header + data)
  File "C:\Users\HEEKWON\anaconda3\envs\reinforcementLearningProject_2\lib\site-packages\wandb\sdk\lib\sock_client.py", line 130, in _sendall_with_error_handle
    sent = self._sock.send(data)
ConnectionAbortedError: [WinError 10053] 현재 연결은 사용자의 호스트 시스템의 소프트웨어의 의해 중단되었습니다
2025-06-03 17:43:26,455 ERROR   MainThread:25396 [redirect.py:_on_write():664] [no run ID] error in stderr callback
Traceback (most recent call last):
  File "C:\Users\HEEKWON\anaconda3\envs\reinforcementLearningProject_2\lib\site-packages\wandb\sdk\lib\redirect.py", line 662, in _on_write
    cb(written_data)
  File "C:\Users\HEEKWON\anaconda3\envs\reinforcementLearningProject_2\lib\site-packages\wandb\sdk\wandb_run.py", line 2500, in <lambda>
    lambda data: self._console_raw_callback("stderr", data),
  File "C:\Users\HEEKWON\anaconda3\envs\reinforcementLearningProject_2\lib\site-packages\wandb\sdk\wandb_run.py", line 406, in wrapper
    return func(self, *args, **kwargs)
  File "C:\Users\HEEKWON\anaconda3\envs\reinforcementLearningProject_2\lib\site-packages\wandb\sdk\wandb_run.py", line 464, in wrapper_fn
    return func(self, *args, **kwargs)
  File "C:\Users\HEEKWON\anaconda3\envs\reinforcementLearningProject_2\lib\site-packages\wandb\sdk\wandb_run.py", line 1639, in _console_raw_callback
    self._backend.interface.publish_output_raw(name, data)
  File "C:\Users\HEEKWON\anaconda3\envs\reinforcementLearningProject_2\lib\site-packages\wandb\sdk\interface\interface.py", line 762, in publish_output_raw
    self._publish_output_raw(o)
  File "C:\Users\HEEKWON\anaconda3\envs\reinforcementLearningProject_2\lib\site-packages\wandb\sdk\interface\interface_shared.py", line 38, in _publish_output_raw
    self._publish(rec)
  File "C:\Users\HEEKWON\anaconda3\envs\reinforcementLearningProject_2\lib\site-packages\wandb\sdk\interface\interface_sock.py", line 39, in _publish
    self._sock_client.send_record_publish(record)
  File "C:\Users\HEEKWON\anaconda3\envs\reinforcementLearningProject_2\lib\site-packages\wandb\sdk\lib\sock_client.py", line 174, in send_record_publish
    self.send_server_request(server_req)
  File "C:\Users\HEEKWON\anaconda3\envs\reinforcementLearningProject_2\lib\site-packages\wandb\sdk\lib\sock_client.py", line 154, in send_server_request
    self._send_message(msg)
  File "C:\Users\HEEKWON\anaconda3\envs\reinforcementLearningProject_2\lib\site-packages\wandb\sdk\lib\sock_client.py", line 151, in _send_message
    self._sendall_with_error_handle(header + data)
  File "C:\Users\HEEKWON\anaconda3\envs\reinforcementLearningProject_2\lib\site-packages\wandb\sdk\lib\sock_client.py", line 130, in _sendall_with_error_handle
    sent = self._sock.send(data)
ConnectionAbortedError: [WinError 10053] 현재 연결은 사용자의 호스트 시스템의 소프트웨어의 의해 중단되었습니다
2025-06-03 17:43:26,456 ERROR   MainThread:25396 [redirect.py:_on_write():664] [no run ID] error in stderr callback
Traceback (most recent call last):
  File "C:\Users\HEEKWON\anaconda3\envs\reinforcementLearningProject_2\lib\site-packages\wandb\sdk\lib\redirect.py", line 662, in _on_write
    cb(written_data)
  File "C:\Users\HEEKWON\anaconda3\envs\reinforcementLearningProject_2\lib\site-packages\wandb\sdk\wandb_run.py", line 2500, in <lambda>
    lambda data: self._console_raw_callback("stderr", data),
  File "C:\Users\HEEKWON\anaconda3\envs\reinforcementLearningProject_2\lib\site-packages\wandb\sdk\wandb_run.py", line 406, in wrapper
    return func(self, *args, **kwargs)
  File "C:\Users\HEEKWON\anaconda3\envs\reinforcementLearningProject_2\lib\site-packages\wandb\sdk\wandb_run.py", line 464, in wrapper_fn
    return func(self, *args, **kwargs)
  File "C:\Users\HEEKWON\anaconda3\envs\reinforcementLearningProject_2\lib\site-packages\wandb\sdk\wandb_run.py", line 1639, in _console_raw_callback
    self._backend.interface.publish_output_raw(name, data)
  File "C:\Users\HEEKWON\anaconda3\envs\reinforcementLearningProject_2\lib\site-packages\wandb\sdk\interface\interface.py", line 762, in publish_output_raw
    self._publish_output_raw(o)
  File "C:\Users\HEEKWON\anaconda3\envs\reinforcementLearningProject_2\lib\site-packages\wandb\sdk\interface\interface_shared.py", line 38, in _publish_output_raw
    self._publish(rec)
  File "C:\Users\HEEKWON\anaconda3\envs\reinforcementLearningProject_2\lib\site-packages\wandb\sdk\interface\interface_sock.py", line 39, in _publish
    self._sock_client.send_record_publish(record)
  File "C:\Users\HEEKWON\anaconda3\envs\reinforcementLearningProject_2\lib\site-packages\wandb\sdk\lib\sock_client.py", line 174, in send_record_publish
    self.send_server_request(server_req)
  File "C:\Users\HEEKWON\anaconda3\envs\reinforcementLearningProject_2\lib\site-packages\wandb\sdk\lib\sock_client.py", line 154, in send_server_request
    self._send_message(msg)
  File "C:\Users\HEEKWON\anaconda3\envs\reinforcementLearningProject_2\lib\site-packages\wandb\sdk\lib\sock_client.py", line 151, in _send_message
    self._sendall_with_error_handle(header + data)
  File "C:\Users\HEEKWON\anaconda3\envs\reinforcementLearningProject_2\lib\site-packages\wandb\sdk\lib\sock_client.py", line 130, in _sendall_with_error_handle
    sent = self._sock.send(data)
ConnectionAbortedError: [WinError 10053] 현재 연결은 사용자의 호스트 시스템의 소프트웨어의 의해 중단되었습니다
2025-06-03 17:43:26,456 ERROR   MainThread:25396 [redirect.py:_on_write():664] [no run ID] error in stderr callback
Traceback (most recent call last):
  File "C:\Users\HEEKWON\anaconda3\envs\reinforcementLearningProject_2\lib\site-packages\wandb\sdk\lib\redirect.py", line 662, in _on_write
    cb(written_data)
  File "C:\Users\HEEKWON\anaconda3\envs\reinforcementLearningProject_2\lib\site-packages\wandb\sdk\wandb_run.py", line 2500, in <lambda>
    lambda data: self._console_raw_callback("stderr", data),
  File "C:\Users\HEEKWON\anaconda3\envs\reinforcementLearningProject_2\lib\site-packages\wandb\sdk\wandb_run.py", line 406, in wrapper
    return func(self, *args, **kwargs)
  File "C:\Users\HEEKWON\anaconda3\envs\reinforcementLearningProject_2\lib\site-packages\wandb\sdk\wandb_run.py", line 464, in wrapper_fn
    return func(self, *args, **kwargs)
  File "C:\Users\HEEKWON\anaconda3\envs\reinforcementLearningProject_2\lib\site-packages\wandb\sdk\wandb_run.py", line 1639, in _console_raw_callback
    self._backend.interface.publish_output_raw(name, data)
  File "C:\Users\HEEKWON\anaconda3\envs\reinforcementLearningProject_2\lib\site-packages\wandb\sdk\interface\interface.py", line 762, in publish_output_raw
    self._publish_output_raw(o)
  File "C:\Users\HEEKWON\anaconda3\envs\reinforcementLearningProject_2\lib\site-packages\wandb\sdk\interface\interface_shared.py", line 38, in _publish_output_raw
    self._publish(rec)
  File "C:\Users\HEEKWON\anaconda3\envs\reinforcementLearningProject_2\lib\site-packages\wandb\sdk\interface\interface_sock.py", line 39, in _publish
    self._sock_client.send_record_publish(record)
  File "C:\Users\HEEKWON\anaconda3\envs\reinforcementLearningProject_2\lib\site-packages\wandb\sdk\lib\sock_client.py", line 174, in send_record_publish
    self.send_server_request(server_req)
  File "C:\Users\HEEKWON\anaconda3\envs\reinforcementLearningProject_2\lib\site-packages\wandb\sdk\lib\sock_client.py", line 154, in send_server_request
    self._send_message(msg)
  File "C:\Users\HEEKWON\anaconda3\envs\reinforcementLearningProject_2\lib\site-packages\wandb\sdk\lib\sock_client.py", line 151, in _send_message
    self._sendall_with_error_handle(header + data)
  File "C:\Users\HEEKWON\anaconda3\envs\reinforcementLearningProject_2\lib\site-packages\wandb\sdk\lib\sock_client.py", line 130, in _sendall_with_error_handle
    sent = self._sock.send(data)
ConnectionAbortedError: [WinError 10053] 현재 연결은 사용자의 호스트 시스템의 소프트웨어의 의해 중단되었습니다
2025-06-03 17:43:26,457 ERROR   MainThread:25396 [redirect.py:_on_write():664] [no run ID] error in stderr callback
Traceback (most recent call last):
  File "C:\Users\HEEKWON\anaconda3\envs\reinforcementLearningProject_2\lib\site-packages\wandb\sdk\lib\redirect.py", line 662, in _on_write
    cb(written_data)
  File "C:\Users\HEEKWON\anaconda3\envs\reinforcementLearningProject_2\lib\site-packages\wandb\sdk\wandb_run.py", line 2500, in <lambda>
    lambda data: self._console_raw_callback("stderr", data),
  File "C:\Users\HEEKWON\anaconda3\envs\reinforcementLearningProject_2\lib\site-packages\wandb\sdk\wandb_run.py", line 406, in wrapper
    return func(self, *args, **kwargs)
  File "C:\Users\HEEKWON\anaconda3\envs\reinforcementLearningProject_2\lib\site-packages\wandb\sdk\wandb_run.py", line 464, in wrapper_fn
    return func(self, *args, **kwargs)
  File "C:\Users\HEEKWON\anaconda3\envs\reinforcementLearningProject_2\lib\site-packages\wandb\sdk\wandb_run.py", line 1639, in _console_raw_callback
    self._backend.interface.publish_output_raw(name, data)
  File "C:\Users\HEEKWON\anaconda3\envs\reinforcementLearningProject_2\lib\site-packages\wandb\sdk\interface\interface.py", line 762, in publish_output_raw
    self._publish_output_raw(o)
  File "C:\Users\HEEKWON\anaconda3\envs\reinforcementLearningProject_2\lib\site-packages\wandb\sdk\interface\interface_shared.py", line 38, in _publish_output_raw
    self._publish(rec)
  File "C:\Users\HEEKWON\anaconda3\envs\reinforcementLearningProject_2\lib\site-packages\wandb\sdk\interface\interface_sock.py", line 39, in _publish
    self._sock_client.send_record_publish(record)
  File "C:\Users\HEEKWON\anaconda3\envs\reinforcementLearningProject_2\lib\site-packages\wandb\sdk\lib\sock_client.py", line 174, in send_record_publish
    self.send_server_request(server_req)
  File "C:\Users\HEEKWON\anaconda3\envs\reinforcementLearningProject_2\lib\site-packages\wandb\sdk\lib\sock_client.py", line 154, in send_server_request
    self._send_message(msg)
  File "C:\Users\HEEKWON\anaconda3\envs\reinforcementLearningProject_2\lib\site-packages\wandb\sdk\lib\sock_client.py", line 151, in _send_message
    self._sendall_with_error_handle(header + data)
  File "C:\Users\HEEKWON\anaconda3\envs\reinforcementLearningProject_2\lib\site-packages\wandb\sdk\lib\sock_client.py", line 130, in _sendall_with_error_handle
    sent = self._sock.send(data)
ConnectionAbortedError: [WinError 10053] 현재 연결은 사용자의 호스트 시스템의 소프트웨어의 의해 중단되었습니다
2025-06-03 17:43:26,457 ERROR   MainThread:25396 [redirect.py:_on_write():664] [no run ID] error in stderr callback
Traceback (most recent call last):
  File "C:\Users\HEEKWON\anaconda3\envs\reinforcementLearningProject_2\lib\site-packages\wandb\sdk\lib\redirect.py", line 662, in _on_write
    cb(written_data)
  File "C:\Users\HEEKWON\anaconda3\envs\reinforcementLearningProject_2\lib\site-packages\wandb\sdk\wandb_run.py", line 2500, in <lambda>
    lambda data: self._console_raw_callback("stderr", data),
  File "C:\Users\HEEKWON\anaconda3\envs\reinforcementLearningProject_2\lib\site-packages\wandb\sdk\wandb_run.py", line 406, in wrapper
    return func(self, *args, **kwargs)
  File "C:\Users\HEEKWON\anaconda3\envs\reinforcementLearningProject_2\lib\site-packages\wandb\sdk\wandb_run.py", line 464, in wrapper_fn
    return func(self, *args, **kwargs)
  File "C:\Users\HEEKWON\anaconda3\envs\reinforcementLearningProject_2\lib\site-packages\wandb\sdk\wandb_run.py", line 1639, in _console_raw_callback
    self._backend.interface.publish_output_raw(name, data)
  File "C:\Users\HEEKWON\anaconda3\envs\reinforcementLearningProject_2\lib\site-packages\wandb\sdk\interface\interface.py", line 762, in publish_output_raw
    self._publish_output_raw(o)
  File "C:\Users\HEEKWON\anaconda3\envs\reinforcementLearningProject_2\lib\site-packages\wandb\sdk\interface\interface_shared.py", line 38, in _publish_output_raw
    self._publish(rec)
  File "C:\Users\HEEKWON\anaconda3\envs\reinforcementLearningProject_2\lib\site-packages\wandb\sdk\interface\interface_sock.py", line 39, in _publish
    self._sock_client.send_record_publish(record)
  File "C:\Users\HEEKWON\anaconda3\envs\reinforcementLearningProject_2\lib\site-packages\wandb\sdk\lib\sock_client.py", line 174, in send_record_publish
    self.send_server_request(server_req)
  File "C:\Users\HEEKWON\anaconda3\envs\reinforcementLearningProject_2\lib\site-packages\wandb\sdk\lib\sock_client.py", line 154, in send_server_request
    self._send_message(msg)
  File "C:\Users\HEEKWON\anaconda3\envs\reinforcementLearningProject_2\lib\site-packages\wandb\sdk\lib\sock_client.py", line 151, in _send_message
    self._sendall_with_error_handle(header + data)
  File "C:\Users\HEEKWON\anaconda3\envs\reinforcementLearningProject_2\lib\site-packages\wandb\sdk\lib\sock_client.py", line 130, in _sendall_with_error_handle
    sent = self._sock.send(data)
ConnectionAbortedError: [WinError 10053] 현재 연결은 사용자의 호스트 시스템의 소프트웨어의 의해 중단되었습니다
2025-06-03 17:43:26,458 ERROR   MainThread:25396 [redirect.py:_on_write():664] [no run ID] error in stderr callback
Traceback (most recent call last):
  File "C:\Users\HEEKWON\anaconda3\envs\reinforcementLearningProject_2\lib\site-packages\wandb\sdk\lib\redirect.py", line 662, in _on_write
    cb(written_data)
  File "C:\Users\HEEKWON\anaconda3\envs\reinforcementLearningProject_2\lib\site-packages\wandb\sdk\wandb_run.py", line 2500, in <lambda>
    lambda data: self._console_raw_callback("stderr", data),
  File "C:\Users\HEEKWON\anaconda3\envs\reinforcementLearningProject_2\lib\site-packages\wandb\sdk\wandb_run.py", line 406, in wrapper
    return func(self, *args, **kwargs)
  File "C:\Users\HEEKWON\anaconda3\envs\reinforcementLearningProject_2\lib\site-packages\wandb\sdk\wandb_run.py", line 464, in wrapper_fn
    return func(self, *args, **kwargs)
  File "C:\Users\HEEKWON\anaconda3\envs\reinforcementLearningProject_2\lib\site-packages\wandb\sdk\wandb_run.py", line 1639, in _console_raw_callback
    self._backend.interface.publish_output_raw(name, data)
  File "C:\Users\HEEKWON\anaconda3\envs\reinforcementLearningProject_2\lib\site-packages\wandb\sdk\interface\interface.py", line 762, in publish_output_raw
    self._publish_output_raw(o)
  File "C:\Users\HEEKWON\anaconda3\envs\reinforcementLearningProject_2\lib\site-packages\wandb\sdk\interface\interface_shared.py", line 38, in _publish_output_raw
    self._publish(rec)
  File "C:\Users\HEEKWON\anaconda3\envs\reinforcementLearningProject_2\lib\site-packages\wandb\sdk\interface\interface_sock.py", line 39, in _publish
    self._sock_client.send_record_publish(record)
  File "C:\Users\HEEKWON\anaconda3\envs\reinforcementLearningProject_2\lib\site-packages\wandb\sdk\lib\sock_client.py", line 174, in send_record_publish
    self.send_server_request(server_req)
  File "C:\Users\HEEKWON\anaconda3\envs\reinforcementLearningProject_2\lib\site-packages\wandb\sdk\lib\sock_client.py", line 154, in send_server_request
    self._send_message(msg)
  File "C:\Users\HEEKWON\anaconda3\envs\reinforcementLearningProject_2\lib\site-packages\wandb\sdk\lib\sock_client.py", line 151, in _send_message
    self._sendall_with_error_handle(header + data)
  File "C:\Users\HEEKWON\anaconda3\envs\reinforcementLearningProject_2\lib\site-packages\wandb\sdk\lib\sock_client.py", line 130, in _sendall_with_error_handle
    sent = self._sock.send(data)
ConnectionAbortedError: [WinError 10053] 현재 연결은 사용자의 호스트 시스템의 소프트웨어의 의해 중단되었습니다
2025-06-03 17:43:26,458 ERROR   MainThread:25396 [redirect.py:_on_write():664] [no run ID] error in stderr callback
Traceback (most recent call last):
  File "C:\Users\HEEKWON\anaconda3\envs\reinforcementLearningProject_2\lib\site-packages\wandb\sdk\lib\redirect.py", line 662, in _on_write
    cb(written_data)
  File "C:\Users\HEEKWON\anaconda3\envs\reinforcementLearningProject_2\lib\site-packages\wandb\sdk\wandb_run.py", line 2500, in <lambda>
    lambda data: self._console_raw_callback("stderr", data),
  File "C:\Users\HEEKWON\anaconda3\envs\reinforcementLearningProject_2\lib\site-packages\wandb\sdk\wandb_run.py", line 406, in wrapper
    return func(self, *args, **kwargs)
  File "C:\Users\HEEKWON\anaconda3\envs\reinforcementLearningProject_2\lib\site-packages\wandb\sdk\wandb_run.py", line 464, in wrapper_fn
    return func(self, *args, **kwargs)
  File "C:\Users\HEEKWON\anaconda3\envs\reinforcementLearningProject_2\lib\site-packages\wandb\sdk\wandb_run.py", line 1639, in _console_raw_callback
    self._backend.interface.publish_output_raw(name, data)
  File "C:\Users\HEEKWON\anaconda3\envs\reinforcementLearningProject_2\lib\site-packages\wandb\sdk\interface\interface.py", line 762, in publish_output_raw
    self._publish_output_raw(o)
  File "C:\Users\HEEKWON\anaconda3\envs\reinforcementLearningProject_2\lib\site-packages\wandb\sdk\interface\interface_shared.py", line 38, in _publish_output_raw
    self._publish(rec)
  File "C:\Users\HEEKWON\anaconda3\envs\reinforcementLearningProject_2\lib\site-packages\wandb\sdk\interface\interface_sock.py", line 39, in _publish
    self._sock_client.send_record_publish(record)
  File "C:\Users\HEEKWON\anaconda3\envs\reinforcementLearningProject_2\lib\site-packages\wandb\sdk\lib\sock_client.py", line 174, in send_record_publish
    self.send_server_request(server_req)
  File "C:\Users\HEEKWON\anaconda3\envs\reinforcementLearningProject_2\lib\site-packages\wandb\sdk\lib\sock_client.py", line 154, in send_server_request
    self._send_message(msg)
  File "C:\Users\HEEKWON\anaconda3\envs\reinforcementLearningProject_2\lib\site-packages\wandb\sdk\lib\sock_client.py", line 151, in _send_message
    self._sendall_with_error_handle(header + data)
  File "C:\Users\HEEKWON\anaconda3\envs\reinforcementLearningProject_2\lib\site-packages\wandb\sdk\lib\sock_client.py", line 130, in _sendall_with_error_handle
    sent = self._sock.send(data)
ConnectionAbortedError: [WinError 10053] 현재 연결은 사용자의 호스트 시스템의 소프트웨어의 의해 중단되었습니다
2025-06-03 17:43:26,459 ERROR   MainThread:25396 [redirect.py:_on_write():664] [no run ID] error in stderr callback
Traceback (most recent call last):
  File "C:\Users\HEEKWON\anaconda3\envs\reinforcementLearningProject_2\lib\site-packages\wandb\sdk\lib\redirect.py", line 662, in _on_write
    cb(written_data)
  File "C:\Users\HEEKWON\anaconda3\envs\reinforcementLearningProject_2\lib\site-packages\wandb\sdk\wandb_run.py", line 2500, in <lambda>
    lambda data: self._console_raw_callback("stderr", data),
  File "C:\Users\HEEKWON\anaconda3\envs\reinforcementLearningProject_2\lib\site-packages\wandb\sdk\wandb_run.py", line 406, in wrapper
    return func(self, *args, **kwargs)
  File "C:\Users\HEEKWON\anaconda3\envs\reinforcementLearningProject_2\lib\site-packages\wandb\sdk\wandb_run.py", line 464, in wrapper_fn
    return func(self, *args, **kwargs)
  File "C:\Users\HEEKWON\anaconda3\envs\reinforcementLearningProject_2\lib\site-packages\wandb\sdk\wandb_run.py", line 1639, in _console_raw_callback
    self._backend.interface.publish_output_raw(name, data)
  File "C:\Users\HEEKWON\anaconda3\envs\reinforcementLearningProject_2\lib\site-packages\wandb\sdk\interface\interface.py", line 762, in publish_output_raw
    self._publish_output_raw(o)
  File "C:\Users\HEEKWON\anaconda3\envs\reinforcementLearningProject_2\lib\site-packages\wandb\sdk\interface\interface_shared.py", line 38, in _publish_output_raw
    self._publish(rec)
  File "C:\Users\HEEKWON\anaconda3\envs\reinforcementLearningProject_2\lib\site-packages\wandb\sdk\interface\interface_sock.py", line 39, in _publish
    self._sock_client.send_record_publish(record)
  File "C:\Users\HEEKWON\anaconda3\envs\reinforcementLearningProject_2\lib\site-packages\wandb\sdk\lib\sock_client.py", line 174, in send_record_publish
    self.send_server_request(server_req)
  File "C:\Users\HEEKWON\anaconda3\envs\reinforcementLearningProject_2\lib\site-packages\wandb\sdk\lib\sock_client.py", line 154, in send_server_request
    self._send_message(msg)
  File "C:\Users\HEEKWON\anaconda3\envs\reinforcementLearningProject_2\lib\site-packages\wandb\sdk\lib\sock_client.py", line 151, in _send_message
    self._sendall_with_error_handle(header + data)
  File "C:\Users\HEEKWON\anaconda3\envs\reinforcementLearningProject_2\lib\site-packages\wandb\sdk\lib\sock_client.py", line 130, in _sendall_with_error_handle
    sent = self._sock.send(data)
ConnectionAbortedError: [WinError 10053] 현재 연결은 사용자의 호스트 시스템의 소프트웨어의 의해 중단되었습니다
2025-06-03 17:43:26,459 ERROR   MainThread:25396 [redirect.py:_on_write():664] [no run ID] error in stderr callback
Traceback (most recent call last):
  File "C:\Users\HEEKWON\anaconda3\envs\reinforcementLearningProject_2\lib\site-packages\wandb\sdk\lib\redirect.py", line 662, in _on_write
    cb(written_data)
  File "C:\Users\HEEKWON\anaconda3\envs\reinforcementLearningProject_2\lib\site-packages\wandb\sdk\wandb_run.py", line 2500, in <lambda>
    lambda data: self._console_raw_callback("stderr", data),
  File "C:\Users\HEEKWON\anaconda3\envs\reinforcementLearningProject_2\lib\site-packages\wandb\sdk\wandb_run.py", line 406, in wrapper
    return func(self, *args, **kwargs)
  File "C:\Users\HEEKWON\anaconda3\envs\reinforcementLearningProject_2\lib\site-packages\wandb\sdk\wandb_run.py", line 464, in wrapper_fn
    return func(self, *args, **kwargs)
  File "C:\Users\HEEKWON\anaconda3\envs\reinforcementLearningProject_2\lib\site-packages\wandb\sdk\wandb_run.py", line 1639, in _console_raw_callback
    self._backend.interface.publish_output_raw(name, data)
  File "C:\Users\HEEKWON\anaconda3\envs\reinforcementLearningProject_2\lib\site-packages\wandb\sdk\interface\interface.py", line 762, in publish_output_raw
    self._publish_output_raw(o)
  File "C:\Users\HEEKWON\anaconda3\envs\reinforcementLearningProject_2\lib\site-packages\wandb\sdk\interface\interface_shared.py", line 38, in _publish_output_raw
    self._publish(rec)
  File "C:\Users\HEEKWON\anaconda3\envs\reinforcementLearningProject_2\lib\site-packages\wandb\sdk\interface\interface_sock.py", line 39, in _publish
    self._sock_client.send_record_publish(record)
  File "C:\Users\HEEKWON\anaconda3\envs\reinforcementLearningProject_2\lib\site-packages\wandb\sdk\lib\sock_client.py", line 174, in send_record_publish
    self.send_server_request(server_req)
  File "C:\Users\HEEKWON\anaconda3\envs\reinforcementLearningProject_2\lib\site-packages\wandb\sdk\lib\sock_client.py", line 154, in send_server_request
    self._send_message(msg)
  File "C:\Users\HEEKWON\anaconda3\envs\reinforcementLearningProject_2\lib\site-packages\wandb\sdk\lib\sock_client.py", line 151, in _send_message
    self._sendall_with_error_handle(header + data)
  File "C:\Users\HEEKWON\anaconda3\envs\reinforcementLearningProject_2\lib\site-packages\wandb\sdk\lib\sock_client.py", line 130, in _sendall_with_error_handle
    sent = self._sock.send(data)
ConnectionAbortedError: [WinError 10053] 현재 연결은 사용자의 호스트 시스템의 소프트웨어의 의해 중단되었습니다
2025-06-03 17:43:26,460 ERROR   MainThread:25396 [redirect.py:_on_write():664] [no run ID] error in stderr callback
Traceback (most recent call last):
  File "C:\Users\HEEKWON\anaconda3\envs\reinforcementLearningProject_2\lib\site-packages\wandb\sdk\lib\redirect.py", line 662, in _on_write
    cb(written_data)
  File "C:\Users\HEEKWON\anaconda3\envs\reinforcementLearningProject_2\lib\site-packages\wandb\sdk\wandb_run.py", line 2500, in <lambda>
    lambda data: self._console_raw_callback("stderr", data),
  File "C:\Users\HEEKWON\anaconda3\envs\reinforcementLearningProject_2\lib\site-packages\wandb\sdk\wandb_run.py", line 406, in wrapper
    return func(self, *args, **kwargs)
  File "C:\Users\HEEKWON\anaconda3\envs\reinforcementLearningProject_2\lib\site-packages\wandb\sdk\wandb_run.py", line 464, in wrapper_fn
    return func(self, *args, **kwargs)
  File "C:\Users\HEEKWON\anaconda3\envs\reinforcementLearningProject_2\lib\site-packages\wandb\sdk\wandb_run.py", line 1639, in _console_raw_callback
    self._backend.interface.publish_output_raw(name, data)
  File "C:\Users\HEEKWON\anaconda3\envs\reinforcementLearningProject_2\lib\site-packages\wandb\sdk\interface\interface.py", line 762, in publish_output_raw
    self._publish_output_raw(o)
  File "C:\Users\HEEKWON\anaconda3\envs\reinforcementLearningProject_2\lib\site-packages\wandb\sdk\interface\interface_shared.py", line 38, in _publish_output_raw
    self._publish(rec)
  File "C:\Users\HEEKWON\anaconda3\envs\reinforcementLearningProject_2\lib\site-packages\wandb\sdk\interface\interface_sock.py", line 39, in _publish
    self._sock_client.send_record_publish(record)
  File "C:\Users\HEEKWON\anaconda3\envs\reinforcementLearningProject_2\lib\site-packages\wandb\sdk\lib\sock_client.py", line 174, in send_record_publish
    self.send_server_request(server_req)
  File "C:\Users\HEEKWON\anaconda3\envs\reinforcementLearningProject_2\lib\site-packages\wandb\sdk\lib\sock_client.py", line 154, in send_server_request
    self._send_message(msg)
  File "C:\Users\HEEKWON\anaconda3\envs\reinforcementLearningProject_2\lib\site-packages\wandb\sdk\lib\sock_client.py", line 151, in _send_message
    self._sendall_with_error_handle(header + data)
  File "C:\Users\HEEKWON\anaconda3\envs\reinforcementLearningProject_2\lib\site-packages\wandb\sdk\lib\sock_client.py", line 130, in _sendall_with_error_handle
    sent = self._sock.send(data)
ConnectionAbortedError: [WinError 10053] 현재 연결은 사용자의 호스트 시스템의 소프트웨어의 의해 중단되었습니다
2025-06-03 17:43:26,460 ERROR   MainThread:25396 [redirect.py:_on_write():664] [no run ID] error in stderr callback
Traceback (most recent call last):
  File "C:\Users\HEEKWON\anaconda3\envs\reinforcementLearningProject_2\lib\site-packages\wandb\sdk\lib\redirect.py", line 662, in _on_write
    cb(written_data)
  File "C:\Users\HEEKWON\anaconda3\envs\reinforcementLearningProject_2\lib\site-packages\wandb\sdk\wandb_run.py", line 2500, in <lambda>
    lambda data: self._console_raw_callback("stderr", data),
  File "C:\Users\HEEKWON\anaconda3\envs\reinforcementLearningProject_2\lib\site-packages\wandb\sdk\wandb_run.py", line 406, in wrapper
    return func(self, *args, **kwargs)
  File "C:\Users\HEEKWON\anaconda3\envs\reinforcementLearningProject_2\lib\site-packages\wandb\sdk\wandb_run.py", line 464, in wrapper_fn
    return func(self, *args, **kwargs)
  File "C:\Users\HEEKWON\anaconda3\envs\reinforcementLearningProject_2\lib\site-packages\wandb\sdk\wandb_run.py", line 1639, in _console_raw_callback
    self._backend.interface.publish_output_raw(name, data)
  File "C:\Users\HEEKWON\anaconda3\envs\reinforcementLearningProject_2\lib\site-packages\wandb\sdk\interface\interface.py", line 762, in publish_output_raw
    self._publish_output_raw(o)
  File "C:\Users\HEEKWON\anaconda3\envs\reinforcementLearningProject_2\lib\site-packages\wandb\sdk\interface\interface_shared.py", line 38, in _publish_output_raw
    self._publish(rec)
  File "C:\Users\HEEKWON\anaconda3\envs\reinforcementLearningProject_2\lib\site-packages\wandb\sdk\interface\interface_sock.py", line 39, in _publish
    self._sock_client.send_record_publish(record)
  File "C:\Users\HEEKWON\anaconda3\envs\reinforcementLearningProject_2\lib\site-packages\wandb\sdk\lib\sock_client.py", line 174, in send_record_publish
    self.send_server_request(server_req)
  File "C:\Users\HEEKWON\anaconda3\envs\reinforcementLearningProject_2\lib\site-packages\wandb\sdk\lib\sock_client.py", line 154, in send_server_request
    self._send_message(msg)
  File "C:\Users\HEEKWON\anaconda3\envs\reinforcementLearningProject_2\lib\site-packages\wandb\sdk\lib\sock_client.py", line 151, in _send_message
    self._sendall_with_error_handle(header + data)
  File "C:\Users\HEEKWON\anaconda3\envs\reinforcementLearningProject_2\lib\site-packages\wandb\sdk\lib\sock_client.py", line 130, in _sendall_with_error_handle
    sent = self._sock.send(data)
ConnectionAbortedError: [WinError 10053] 현재 연결은 사용자의 호스트 시스템의 소프트웨어의 의해 중단되었습니다
2025-06-03 17:43:26,460 ERROR   MainThread:25396 [redirect.py:_on_write():664] [no run ID] error in stderr callback
Traceback (most recent call last):
  File "C:\Users\HEEKWON\anaconda3\envs\reinforcementLearningProject_2\lib\site-packages\wandb\sdk\lib\redirect.py", line 662, in _on_write
    cb(written_data)
  File "C:\Users\HEEKWON\anaconda3\envs\reinforcementLearningProject_2\lib\site-packages\wandb\sdk\wandb_run.py", line 2500, in <lambda>
    lambda data: self._console_raw_callback("stderr", data),
  File "C:\Users\HEEKWON\anaconda3\envs\reinforcementLearningProject_2\lib\site-packages\wandb\sdk\wandb_run.py", line 406, in wrapper
    return func(self, *args, **kwargs)
  File "C:\Users\HEEKWON\anaconda3\envs\reinforcementLearningProject_2\lib\site-packages\wandb\sdk\wandb_run.py", line 464, in wrapper_fn
    return func(self, *args, **kwargs)
  File "C:\Users\HEEKWON\anaconda3\envs\reinforcementLearningProject_2\lib\site-packages\wandb\sdk\wandb_run.py", line 1639, in _console_raw_callback
    self._backend.interface.publish_output_raw(name, data)
  File "C:\Users\HEEKWON\anaconda3\envs\reinforcementLearningProject_2\lib\site-packages\wandb\sdk\interface\interface.py", line 762, in publish_output_raw
    self._publish_output_raw(o)
  File "C:\Users\HEEKWON\anaconda3\envs\reinforcementLearningProject_2\lib\site-packages\wandb\sdk\interface\interface_shared.py", line 38, in _publish_output_raw
    self._publish(rec)
  File "C:\Users\HEEKWON\anaconda3\envs\reinforcementLearningProject_2\lib\site-packages\wandb\sdk\interface\interface_sock.py", line 39, in _publish
    self._sock_client.send_record_publish(record)
  File "C:\Users\HEEKWON\anaconda3\envs\reinforcementLearningProject_2\lib\site-packages\wandb\sdk\lib\sock_client.py", line 174, in send_record_publish
    self.send_server_request(server_req)
  File "C:\Users\HEEKWON\anaconda3\envs\reinforcementLearningProject_2\lib\site-packages\wandb\sdk\lib\sock_client.py", line 154, in send_server_request
    self._send_message(msg)
  File "C:\Users\HEEKWON\anaconda3\envs\reinforcementLearningProject_2\lib\site-packages\wandb\sdk\lib\sock_client.py", line 151, in _send_message
    self._sendall_with_error_handle(header + data)
  File "C:\Users\HEEKWON\anaconda3\envs\reinforcementLearningProject_2\lib\site-packages\wandb\sdk\lib\sock_client.py", line 130, in _sendall_with_error_handle
    sent = self._sock.send(data)
ConnectionAbortedError: [WinError 10053] 현재 연결은 사용자의 호스트 시스템의 소프트웨어의 의해 중단되었습니다
2025-06-03 17:43:26,460 ERROR   MainThread:25396 [redirect.py:_on_write():664] [no run ID] error in stderr callback
Traceback (most recent call last):
  File "C:\Users\HEEKWON\anaconda3\envs\reinforcementLearningProject_2\lib\site-packages\wandb\sdk\lib\redirect.py", line 662, in _on_write
    cb(written_data)
  File "C:\Users\HEEKWON\anaconda3\envs\reinforcementLearningProject_2\lib\site-packages\wandb\sdk\wandb_run.py", line 2500, in <lambda>
    lambda data: self._console_raw_callback("stderr", data),
  File "C:\Users\HEEKWON\anaconda3\envs\reinforcementLearningProject_2\lib\site-packages\wandb\sdk\wandb_run.py", line 406, in wrapper
    return func(self, *args, **kwargs)
  File "C:\Users\HEEKWON\anaconda3\envs\reinforcementLearningProject_2\lib\site-packages\wandb\sdk\wandb_run.py", line 464, in wrapper_fn
    return func(self, *args, **kwargs)
  File "C:\Users\HEEKWON\anaconda3\envs\reinforcementLearningProject_2\lib\site-packages\wandb\sdk\wandb_run.py", line 1639, in _console_raw_callback
    self._backend.interface.publish_output_raw(name, data)
  File "C:\Users\HEEKWON\anaconda3\envs\reinforcementLearningProject_2\lib\site-packages\wandb\sdk\interface\interface.py", line 762, in publish_output_raw
    self._publish_output_raw(o)
  File "C:\Users\HEEKWON\anaconda3\envs\reinforcementLearningProject_2\lib\site-packages\wandb\sdk\interface\interface_shared.py", line 38, in _publish_output_raw
    self._publish(rec)
  File "C:\Users\HEEKWON\anaconda3\envs\reinforcementLearningProject_2\lib\site-packages\wandb\sdk\interface\interface_sock.py", line 39, in _publish
    self._sock_client.send_record_publish(record)
  File "C:\Users\HEEKWON\anaconda3\envs\reinforcementLearningProject_2\lib\site-packages\wandb\sdk\lib\sock_client.py", line 174, in send_record_publish
    self.send_server_request(server_req)
  File "C:\Users\HEEKWON\anaconda3\envs\reinforcementLearningProject_2\lib\site-packages\wandb\sdk\lib\sock_client.py", line 154, in send_server_request
    self._send_message(msg)
  File "C:\Users\HEEKWON\anaconda3\envs\reinforcementLearningProject_2\lib\site-packages\wandb\sdk\lib\sock_client.py", line 151, in _send_message
    self._sendall_with_error_handle(header + data)
  File "C:\Users\HEEKWON\anaconda3\envs\reinforcementLearningProject_2\lib\site-packages\wandb\sdk\lib\sock_client.py", line 130, in _sendall_with_error_handle
    sent = self._sock.send(data)
ConnectionAbortedError: [WinError 10053] 현재 연결은 사용자의 호스트 시스템의 소프트웨어의 의해 중단되었습니다
2025-06-03 17:43:26,461 ERROR   MainThread:25396 [redirect.py:_on_write():664] [no run ID] error in stderr callback
Traceback (most recent call last):
  File "C:\Users\HEEKWON\anaconda3\envs\reinforcementLearningProject_2\lib\site-packages\wandb\sdk\lib\redirect.py", line 662, in _on_write
    cb(written_data)
  File "C:\Users\HEEKWON\anaconda3\envs\reinforcementLearningProject_2\lib\site-packages\wandb\sdk\wandb_run.py", line 2500, in <lambda>
    lambda data: self._console_raw_callback("stderr", data),
  File "C:\Users\HEEKWON\anaconda3\envs\reinforcementLearningProject_2\lib\site-packages\wandb\sdk\wandb_run.py", line 406, in wrapper
    return func(self, *args, **kwargs)
  File "C:\Users\HEEKWON\anaconda3\envs\reinforcementLearningProject_2\lib\site-packages\wandb\sdk\wandb_run.py", line 464, in wrapper_fn
    return func(self, *args, **kwargs)
  File "C:\Users\HEEKWON\anaconda3\envs\reinforcementLearningProject_2\lib\site-packages\wandb\sdk\wandb_run.py", line 1639, in _console_raw_callback
    self._backend.interface.publish_output_raw(name, data)
  File "C:\Users\HEEKWON\anaconda3\envs\reinforcementLearningProject_2\lib\site-packages\wandb\sdk\interface\interface.py", line 762, in publish_output_raw
    self._publish_output_raw(o)
  File "C:\Users\HEEKWON\anaconda3\envs\reinforcementLearningProject_2\lib\site-packages\wandb\sdk\interface\interface_shared.py", line 38, in _publish_output_raw
    self._publish(rec)
  File "C:\Users\HEEKWON\anaconda3\envs\reinforcementLearningProject_2\lib\site-packages\wandb\sdk\interface\interface_sock.py", line 39, in _publish
    self._sock_client.send_record_publish(record)
  File "C:\Users\HEEKWON\anaconda3\envs\reinforcementLearningProject_2\lib\site-packages\wandb\sdk\lib\sock_client.py", line 174, in send_record_publish
    self.send_server_request(server_req)
  File "C:\Users\HEEKWON\anaconda3\envs\reinforcementLearningProject_2\lib\site-packages\wandb\sdk\lib\sock_client.py", line 154, in send_server_request
    self._send_message(msg)
  File "C:\Users\HEEKWON\anaconda3\envs\reinforcementLearningProject_2\lib\site-packages\wandb\sdk\lib\sock_client.py", line 151, in _send_message
    self._sendall_with_error_handle(header + data)
  File "C:\Users\HEEKWON\anaconda3\envs\reinforcementLearningProject_2\lib\site-packages\wandb\sdk\lib\sock_client.py", line 130, in _sendall_with_error_handle
    sent = self._sock.send(data)
ConnectionAbortedError: [WinError 10053] 현재 연결은 사용자의 호스트 시스템의 소프트웨어의 의해 중단되었습니다
2025-06-03 17:43:26,463 ERROR   MainThread:25396 [redirect.py:_on_write():664] [no run ID] error in stderr callback
Traceback (most recent call last):
  File "C:\Users\HEEKWON\anaconda3\envs\reinforcementLearningProject_2\lib\site-packages\wandb\sdk\lib\redirect.py", line 662, in _on_write
    cb(written_data)
  File "C:\Users\HEEKWON\anaconda3\envs\reinforcementLearningProject_2\lib\site-packages\wandb\sdk\wandb_run.py", line 2500, in <lambda>
    lambda data: self._console_raw_callback("stderr", data),
  File "C:\Users\HEEKWON\anaconda3\envs\reinforcementLearningProject_2\lib\site-packages\wandb\sdk\wandb_run.py", line 406, in wrapper
    return func(self, *args, **kwargs)
  File "C:\Users\HEEKWON\anaconda3\envs\reinforcementLearningProject_2\lib\site-packages\wandb\sdk\wandb_run.py", line 464, in wrapper_fn
    return func(self, *args, **kwargs)
  File "C:\Users\HEEKWON\anaconda3\envs\reinforcementLearningProject_2\lib\site-packages\wandb\sdk\wandb_run.py", line 1639, in _console_raw_callback
    self._backend.interface.publish_output_raw(name, data)
  File "C:\Users\HEEKWON\anaconda3\envs\reinforcementLearningProject_2\lib\site-packages\wandb\sdk\interface\interface.py", line 762, in publish_output_raw
    self._publish_output_raw(o)
  File "C:\Users\HEEKWON\anaconda3\envs\reinforcementLearningProject_2\lib\site-packages\wandb\sdk\interface\interface_shared.py", line 38, in _publish_output_raw
    self._publish(rec)
  File "C:\Users\HEEKWON\anaconda3\envs\reinforcementLearningProject_2\lib\site-packages\wandb\sdk\interface\interface_sock.py", line 39, in _publish
    self._sock_client.send_record_publish(record)
  File "C:\Users\HEEKWON\anaconda3\envs\reinforcementLearningProject_2\lib\site-packages\wandb\sdk\lib\sock_client.py", line 174, in send_record_publish
    self.send_server_request(server_req)
  File "C:\Users\HEEKWON\anaconda3\envs\reinforcementLearningProject_2\lib\site-packages\wandb\sdk\lib\sock_client.py", line 154, in send_server_request
    self._send_message(msg)
  File "C:\Users\HEEKWON\anaconda3\envs\reinforcementLearningProject_2\lib\site-packages\wandb\sdk\lib\sock_client.py", line 151, in _send_message
    self._sendall_with_error_handle(header + data)
  File "C:\Users\HEEKWON\anaconda3\envs\reinforcementLearningProject_2\lib\site-packages\wandb\sdk\lib\sock_client.py", line 130, in _sendall_with_error_handle
    sent = self._sock.send(data)
ConnectionAbortedError: [WinError 10053] 현재 연결은 사용자의 호스트 시스템의 소프트웨어의 의해 중단되었습니다
2025-06-03 17:43:26,463 ERROR   MainThread:25396 [redirect.py:_on_write():664] [no run ID] error in stderr callback
Traceback (most recent call last):
  File "C:\Users\HEEKWON\anaconda3\envs\reinforcementLearningProject_2\lib\site-packages\wandb\sdk\lib\redirect.py", line 662, in _on_write
    cb(written_data)
  File "C:\Users\HEEKWON\anaconda3\envs\reinforcementLearningProject_2\lib\site-packages\wandb\sdk\wandb_run.py", line 2500, in <lambda>
    lambda data: self._console_raw_callback("stderr", data),
  File "C:\Users\HEEKWON\anaconda3\envs\reinforcementLearningProject_2\lib\site-packages\wandb\sdk\wandb_run.py", line 406, in wrapper
    return func(self, *args, **kwargs)
  File "C:\Users\HEEKWON\anaconda3\envs\reinforcementLearningProject_2\lib\site-packages\wandb\sdk\wandb_run.py", line 464, in wrapper_fn
    return func(self, *args, **kwargs)
  File "C:\Users\HEEKWON\anaconda3\envs\reinforcementLearningProject_2\lib\site-packages\wandb\sdk\wandb_run.py", line 1639, in _console_raw_callback
    self._backend.interface.publish_output_raw(name, data)
  File "C:\Users\HEEKWON\anaconda3\envs\reinforcementLearningProject_2\lib\site-packages\wandb\sdk\interface\interface.py", line 762, in publish_output_raw
    self._publish_output_raw(o)
  File "C:\Users\HEEKWON\anaconda3\envs\reinforcementLearningProject_2\lib\site-packages\wandb\sdk\interface\interface_shared.py", line 38, in _publish_output_raw
    self._publish(rec)
  File "C:\Users\HEEKWON\anaconda3\envs\reinforcementLearningProject_2\lib\site-packages\wandb\sdk\interface\interface_sock.py", line 39, in _publish
    self._sock_client.send_record_publish(record)
  File "C:\Users\HEEKWON\anaconda3\envs\reinforcementLearningProject_2\lib\site-packages\wandb\sdk\lib\sock_client.py", line 174, in send_record_publish
    self.send_server_request(server_req)
  File "C:\Users\HEEKWON\anaconda3\envs\reinforcementLearningProject_2\lib\site-packages\wandb\sdk\lib\sock_client.py", line 154, in send_server_request
    self._send_message(msg)
  File "C:\Users\HEEKWON\anaconda3\envs\reinforcementLearningProject_2\lib\site-packages\wandb\sdk\lib\sock_client.py", line 151, in _send_message
    self._sendall_with_error_handle(header + data)
  File "C:\Users\HEEKWON\anaconda3\envs\reinforcementLearningProject_2\lib\site-packages\wandb\sdk\lib\sock_client.py", line 130, in _sendall_with_error_handle
    sent = self._sock.send(data)
ConnectionAbortedError: [WinError 10053] 현재 연결은 사용자의 호스트 시스템의 소프트웨어의 의해 중단되었습니다
2025-06-03 17:43:26,463 ERROR   MainThread:25396 [redirect.py:_on_write():664] [no run ID] error in stderr callback
Traceback (most recent call last):
  File "C:\Users\HEEKWON\anaconda3\envs\reinforcementLearningProject_2\lib\site-packages\wandb\sdk\lib\redirect.py", line 662, in _on_write
    cb(written_data)
  File "C:\Users\HEEKWON\anaconda3\envs\reinforcementLearningProject_2\lib\site-packages\wandb\sdk\wandb_run.py", line 2500, in <lambda>
    lambda data: self._console_raw_callback("stderr", data),
  File "C:\Users\HEEKWON\anaconda3\envs\reinforcementLearningProject_2\lib\site-packages\wandb\sdk\wandb_run.py", line 406, in wrapper
    return func(self, *args, **kwargs)
  File "C:\Users\HEEKWON\anaconda3\envs\reinforcementLearningProject_2\lib\site-packages\wandb\sdk\wandb_run.py", line 464, in wrapper_fn
    return func(self, *args, **kwargs)
  File "C:\Users\HEEKWON\anaconda3\envs\reinforcementLearningProject_2\lib\site-packages\wandb\sdk\wandb_run.py", line 1639, in _console_raw_callback
    self._backend.interface.publish_output_raw(name, data)
  File "C:\Users\HEEKWON\anaconda3\envs\reinforcementLearningProject_2\lib\site-packages\wandb\sdk\interface\interface.py", line 762, in publish_output_raw
    self._publish_output_raw(o)
  File "C:\Users\HEEKWON\anaconda3\envs\reinforcementLearningProject_2\lib\site-packages\wandb\sdk\interface\interface_shared.py", line 38, in _publish_output_raw
    self._publish(rec)
  File "C:\Users\HEEKWON\anaconda3\envs\reinforcementLearningProject_2\lib\site-packages\wandb\sdk\interface\interface_sock.py", line 39, in _publish
    self._sock_client.send_record_publish(record)
  File "C:\Users\HEEKWON\anaconda3\envs\reinforcementLearningProject_2\lib\site-packages\wandb\sdk\lib\sock_client.py", line 174, in send_record_publish
    self.send_server_request(server_req)
  File "C:\Users\HEEKWON\anaconda3\envs\reinforcementLearningProject_2\lib\site-packages\wandb\sdk\lib\sock_client.py", line 154, in send_server_request
    self._send_message(msg)
  File "C:\Users\HEEKWON\anaconda3\envs\reinforcementLearningProject_2\lib\site-packages\wandb\sdk\lib\sock_client.py", line 151, in _send_message
    self._sendall_with_error_handle(header + data)
  File "C:\Users\HEEKWON\anaconda3\envs\reinforcementLearningProject_2\lib\site-packages\wandb\sdk\lib\sock_client.py", line 130, in _sendall_with_error_handle
    sent = self._sock.send(data)
ConnectionAbortedError: [WinError 10053] 현재 연결은 사용자의 호스트 시스템의 소프트웨어의 의해 중단되었습니다
2025-06-03 17:43:26,463 ERROR   MainThread:25396 [redirect.py:_on_write():664] [no run ID] error in stderr callback
Traceback (most recent call last):
  File "C:\Users\HEEKWON\anaconda3\envs\reinforcementLearningProject_2\lib\site-packages\wandb\sdk\lib\redirect.py", line 662, in _on_write
    cb(written_data)
  File "C:\Users\HEEKWON\anaconda3\envs\reinforcementLearningProject_2\lib\site-packages\wandb\sdk\wandb_run.py", line 2500, in <lambda>
    lambda data: self._console_raw_callback("stderr", data),
  File "C:\Users\HEEKWON\anaconda3\envs\reinforcementLearningProject_2\lib\site-packages\wandb\sdk\wandb_run.py", line 406, in wrapper
    return func(self, *args, **kwargs)
  File "C:\Users\HEEKWON\anaconda3\envs\reinforcementLearningProject_2\lib\site-packages\wandb\sdk\wandb_run.py", line 464, in wrapper_fn
    return func(self, *args, **kwargs)
  File "C:\Users\HEEKWON\anaconda3\envs\reinforcementLearningProject_2\lib\site-packages\wandb\sdk\wandb_run.py", line 1639, in _console_raw_callback
    self._backend.interface.publish_output_raw(name, data)
  File "C:\Users\HEEKWON\anaconda3\envs\reinforcementLearningProject_2\lib\site-packages\wandb\sdk\interface\interface.py", line 762, in publish_output_raw
    self._publish_output_raw(o)
  File "C:\Users\HEEKWON\anaconda3\envs\reinforcementLearningProject_2\lib\site-packages\wandb\sdk\interface\interface_shared.py", line 38, in _publish_output_raw
    self._publish(rec)
  File "C:\Users\HEEKWON\anaconda3\envs\reinforcementLearningProject_2\lib\site-packages\wandb\sdk\interface\interface_sock.py", line 39, in _publish
    self._sock_client.send_record_publish(record)
  File "C:\Users\HEEKWON\anaconda3\envs\reinforcementLearningProject_2\lib\site-packages\wandb\sdk\lib\sock_client.py", line 174, in send_record_publish
    self.send_server_request(server_req)
  File "C:\Users\HEEKWON\anaconda3\envs\reinforcementLearningProject_2\lib\site-packages\wandb\sdk\lib\sock_client.py", line 154, in send_server_request
    self._send_message(msg)
  File "C:\Users\HEEKWON\anaconda3\envs\reinforcementLearningProject_2\lib\site-packages\wandb\sdk\lib\sock_client.py", line 151, in _send_message
    self._sendall_with_error_handle(header + data)
  File "C:\Users\HEEKWON\anaconda3\envs\reinforcementLearningProject_2\lib\site-packages\wandb\sdk\lib\sock_client.py", line 130, in _sendall_with_error_handle
    sent = self._sock.send(data)
ConnectionAbortedError: [WinError 10053] 현재 연결은 사용자의 호스트 시스템의 소프트웨어의 의해 중단되었습니다
2025-06-03 17:43:26,465 ERROR   MainThread:25396 [redirect.py:_on_write():664] [no run ID] error in stderr callback
Traceback (most recent call last):
  File "C:\Users\HEEKWON\anaconda3\envs\reinforcementLearningProject_2\lib\site-packages\wandb\sdk\lib\redirect.py", line 662, in _on_write
    cb(written_data)
  File "C:\Users\HEEKWON\anaconda3\envs\reinforcementLearningProject_2\lib\site-packages\wandb\sdk\wandb_run.py", line 2500, in <lambda>
    lambda data: self._console_raw_callback("stderr", data),
  File "C:\Users\HEEKWON\anaconda3\envs\reinforcementLearningProject_2\lib\site-packages\wandb\sdk\wandb_run.py", line 406, in wrapper
    return func(self, *args, **kwargs)
  File "C:\Users\HEEKWON\anaconda3\envs\reinforcementLearningProject_2\lib\site-packages\wandb\sdk\wandb_run.py", line 464, in wrapper_fn
    return func(self, *args, **kwargs)
  File "C:\Users\HEEKWON\anaconda3\envs\reinforcementLearningProject_2\lib\site-packages\wandb\sdk\wandb_run.py", line 1639, in _console_raw_callback
    self._backend.interface.publish_output_raw(name, data)
  File "C:\Users\HEEKWON\anaconda3\envs\reinforcementLearningProject_2\lib\site-packages\wandb\sdk\interface\interface.py", line 762, in publish_output_raw
    self._publish_output_raw(o)
  File "C:\Users\HEEKWON\anaconda3\envs\reinforcementLearningProject_2\lib\site-packages\wandb\sdk\interface\interface_shared.py", line 38, in _publish_output_raw
    self._publish(rec)
  File "C:\Users\HEEKWON\anaconda3\envs\reinforcementLearningProject_2\lib\site-packages\wandb\sdk\interface\interface_sock.py", line 39, in _publish
    self._sock_client.send_record_publish(record)
  File "C:\Users\HEEKWON\anaconda3\envs\reinforcementLearningProject_2\lib\site-packages\wandb\sdk\lib\sock_client.py", line 174, in send_record_publish
    self.send_server_request(server_req)
  File "C:\Users\HEEKWON\anaconda3\envs\reinforcementLearningProject_2\lib\site-packages\wandb\sdk\lib\sock_client.py", line 154, in send_server_request
    self._send_message(msg)
  File "C:\Users\HEEKWON\anaconda3\envs\reinforcementLearningProject_2\lib\site-packages\wandb\sdk\lib\sock_client.py", line 151, in _send_message
    self._sendall_with_error_handle(header + data)
  File "C:\Users\HEEKWON\anaconda3\envs\reinforcementLearningProject_2\lib\site-packages\wandb\sdk\lib\sock_client.py", line 130, in _sendall_with_error_handle
    sent = self._sock.send(data)
ConnectionAbortedError: [WinError 10053] 현재 연결은 사용자의 호스트 시스템의 소프트웨어의 의해 중단되었습니다
2025-06-03 17:43:26,465 ERROR   MainThread:25396 [redirect.py:_on_write():664] [no run ID] error in stderr callback
Traceback (most recent call last):
  File "C:\Users\HEEKWON\anaconda3\envs\reinforcementLearningProject_2\lib\site-packages\wandb\sdk\lib\redirect.py", line 662, in _on_write
    cb(written_data)
  File "C:\Users\HEEKWON\anaconda3\envs\reinforcementLearningProject_2\lib\site-packages\wandb\sdk\wandb_run.py", line 2500, in <lambda>
    lambda data: self._console_raw_callback("stderr", data),
  File "C:\Users\HEEKWON\anaconda3\envs\reinforcementLearningProject_2\lib\site-packages\wandb\sdk\wandb_run.py", line 406, in wrapper
    return func(self, *args, **kwargs)
  File "C:\Users\HEEKWON\anaconda3\envs\reinforcementLearningProject_2\lib\site-packages\wandb\sdk\wandb_run.py", line 464, in wrapper_fn
    return func(self, *args, **kwargs)
  File "C:\Users\HEEKWON\anaconda3\envs\reinforcementLearningProject_2\lib\site-packages\wandb\sdk\wandb_run.py", line 1639, in _console_raw_callback
    self._backend.interface.publish_output_raw(name, data)
  File "C:\Users\HEEKWON\anaconda3\envs\reinforcementLearningProject_2\lib\site-packages\wandb\sdk\interface\interface.py", line 762, in publish_output_raw
    self._publish_output_raw(o)
  File "C:\Users\HEEKWON\anaconda3\envs\reinforcementLearningProject_2\lib\site-packages\wandb\sdk\interface\interface_shared.py", line 38, in _publish_output_raw
    self._publish(rec)
  File "C:\Users\HEEKWON\anaconda3\envs\reinforcementLearningProject_2\lib\site-packages\wandb\sdk\interface\interface_sock.py", line 39, in _publish
    self._sock_client.send_record_publish(record)
  File "C:\Users\HEEKWON\anaconda3\envs\reinforcementLearningProject_2\lib\site-packages\wandb\sdk\lib\sock_client.py", line 174, in send_record_publish
    self.send_server_request(server_req)
  File "C:\Users\HEEKWON\anaconda3\envs\reinforcementLearningProject_2\lib\site-packages\wandb\sdk\lib\sock_client.py", line 154, in send_server_request
    self._send_message(msg)
  File "C:\Users\HEEKWON\anaconda3\envs\reinforcementLearningProject_2\lib\site-packages\wandb\sdk\lib\sock_client.py", line 151, in _send_message
    self._sendall_with_error_handle(header + data)
  File "C:\Users\HEEKWON\anaconda3\envs\reinforcementLearningProject_2\lib\site-packages\wandb\sdk\lib\sock_client.py", line 130, in _sendall_with_error_handle
    sent = self._sock.send(data)
ConnectionAbortedError: [WinError 10053] 현재 연결은 사용자의 호스트 시스템의 소프트웨어의 의해 중단되었습니다
2025-06-03 17:43:26,465 ERROR   MainThread:25396 [redirect.py:_on_write():664] [no run ID] error in stderr callback
Traceback (most recent call last):
  File "C:\Users\HEEKWON\anaconda3\envs\reinforcementLearningProject_2\lib\site-packages\wandb\sdk\lib\redirect.py", line 662, in _on_write
    cb(written_data)
  File "C:\Users\HEEKWON\anaconda3\envs\reinforcementLearningProject_2\lib\site-packages\wandb\sdk\wandb_run.py", line 2500, in <lambda>
    lambda data: self._console_raw_callback("stderr", data),
  File "C:\Users\HEEKWON\anaconda3\envs\reinforcementLearningProject_2\lib\site-packages\wandb\sdk\wandb_run.py", line 406, in wrapper
    return func(self, *args, **kwargs)
  File "C:\Users\HEEKWON\anaconda3\envs\reinforcementLearningProject_2\lib\site-packages\wandb\sdk\wandb_run.py", line 464, in wrapper_fn
    return func(self, *args, **kwargs)
  File "C:\Users\HEEKWON\anaconda3\envs\reinforcementLearningProject_2\lib\site-packages\wandb\sdk\wandb_run.py", line 1639, in _console_raw_callback
    self._backend.interface.publish_output_raw(name, data)
  File "C:\Users\HEEKWON\anaconda3\envs\reinforcementLearningProject_2\lib\site-packages\wandb\sdk\interface\interface.py", line 762, in publish_output_raw
    self._publish_output_raw(o)
  File "C:\Users\HEEKWON\anaconda3\envs\reinforcementLearningProject_2\lib\site-packages\wandb\sdk\interface\interface_shared.py", line 38, in _publish_output_raw
    self._publish(rec)
  File "C:\Users\HEEKWON\anaconda3\envs\reinforcementLearningProject_2\lib\site-packages\wandb\sdk\interface\interface_sock.py", line 39, in _publish
    self._sock_client.send_record_publish(record)
  File "C:\Users\HEEKWON\anaconda3\envs\reinforcementLearningProject_2\lib\site-packages\wandb\sdk\lib\sock_client.py", line 174, in send_record_publish
    self.send_server_request(server_req)
  File "C:\Users\HEEKWON\anaconda3\envs\reinforcementLearningProject_2\lib\site-packages\wandb\sdk\lib\sock_client.py", line 154, in send_server_request
    self._send_message(msg)
  File "C:\Users\HEEKWON\anaconda3\envs\reinforcementLearningProject_2\lib\site-packages\wandb\sdk\lib\sock_client.py", line 151, in _send_message
    self._sendall_with_error_handle(header + data)
  File "C:\Users\HEEKWON\anaconda3\envs\reinforcementLearningProject_2\lib\site-packages\wandb\sdk\lib\sock_client.py", line 130, in _sendall_with_error_handle
    sent = self._sock.send(data)
ConnectionAbortedError: [WinError 10053] 현재 연결은 사용자의 호스트 시스템의 소프트웨어의 의해 중단되었습니다
2025-06-03 17:43:26,465 ERROR   MainThread:25396 [redirect.py:_on_write():664] [no run ID] error in stderr callback
Traceback (most recent call last):
  File "C:\Users\HEEKWON\anaconda3\envs\reinforcementLearningProject_2\lib\site-packages\wandb\sdk\lib\redirect.py", line 662, in _on_write
    cb(written_data)
  File "C:\Users\HEEKWON\anaconda3\envs\reinforcementLearningProject_2\lib\site-packages\wandb\sdk\wandb_run.py", line 2500, in <lambda>
    lambda data: self._console_raw_callback("stderr", data),
  File "C:\Users\HEEKWON\anaconda3\envs\reinforcementLearningProject_2\lib\site-packages\wandb\sdk\wandb_run.py", line 406, in wrapper
    return func(self, *args, **kwargs)
  File "C:\Users\HEEKWON\anaconda3\envs\reinforcementLearningProject_2\lib\site-packages\wandb\sdk\wandb_run.py", line 464, in wrapper_fn
    return func(self, *args, **kwargs)
  File "C:\Users\HEEKWON\anaconda3\envs\reinforcementLearningProject_2\lib\site-packages\wandb\sdk\wandb_run.py", line 1639, in _console_raw_callback
    self._backend.interface.publish_output_raw(name, data)
  File "C:\Users\HEEKWON\anaconda3\envs\reinforcementLearningProject_2\lib\site-packages\wandb\sdk\interface\interface.py", line 762, in publish_output_raw
    self._publish_output_raw(o)
  File "C:\Users\HEEKWON\anaconda3\envs\reinforcementLearningProject_2\lib\site-packages\wandb\sdk\interface\interface_shared.py", line 38, in _publish_output_raw
    self._publish(rec)
  File "C:\Users\HEEKWON\anaconda3\envs\reinforcementLearningProject_2\lib\site-packages\wandb\sdk\interface\interface_sock.py", line 39, in _publish
    self._sock_client.send_record_publish(record)
  File "C:\Users\HEEKWON\anaconda3\envs\reinforcementLearningProject_2\lib\site-packages\wandb\sdk\lib\sock_client.py", line 174, in send_record_publish
    self.send_server_request(server_req)
  File "C:\Users\HEEKWON\anaconda3\envs\reinforcementLearningProject_2\lib\site-packages\wandb\sdk\lib\sock_client.py", line 154, in send_server_request
    self._send_message(msg)
  File "C:\Users\HEEKWON\anaconda3\envs\reinforcementLearningProject_2\lib\site-packages\wandb\sdk\lib\sock_client.py", line 151, in _send_message
    self._sendall_with_error_handle(header + data)
  File "C:\Users\HEEKWON\anaconda3\envs\reinforcementLearningProject_2\lib\site-packages\wandb\sdk\lib\sock_client.py", line 130, in _sendall_with_error_handle
    sent = self._sock.send(data)
ConnectionAbortedError: [WinError 10053] 현재 연결은 사용자의 호스트 시스템의 소프트웨어의 의해 중단되었습니다
2025-06-03 17:43:26,465 ERROR   MainThread:25396 [redirect.py:_on_write():664] [no run ID] error in stderr callback
Traceback (most recent call last):
  File "C:\Users\HEEKWON\anaconda3\envs\reinforcementLearningProject_2\lib\site-packages\wandb\sdk\lib\redirect.py", line 662, in _on_write
    cb(written_data)
  File "C:\Users\HEEKWON\anaconda3\envs\reinforcementLearningProject_2\lib\site-packages\wandb\sdk\wandb_run.py", line 2500, in <lambda>
    lambda data: self._console_raw_callback("stderr", data),
  File "C:\Users\HEEKWON\anaconda3\envs\reinforcementLearningProject_2\lib\site-packages\wandb\sdk\wandb_run.py", line 406, in wrapper
    return func(self, *args, **kwargs)
  File "C:\Users\HEEKWON\anaconda3\envs\reinforcementLearningProject_2\lib\site-packages\wandb\sdk\wandb_run.py", line 464, in wrapper_fn
    return func(self, *args, **kwargs)
  File "C:\Users\HEEKWON\anaconda3\envs\reinforcementLearningProject_2\lib\site-packages\wandb\sdk\wandb_run.py", line 1639, in _console_raw_callback
    self._backend.interface.publish_output_raw(name, data)
  File "C:\Users\HEEKWON\anaconda3\envs\reinforcementLearningProject_2\lib\site-packages\wandb\sdk\interface\interface.py", line 762, in publish_output_raw
    self._publish_output_raw(o)
  File "C:\Users\HEEKWON\anaconda3\envs\reinforcementLearningProject_2\lib\site-packages\wandb\sdk\interface\interface_shared.py", line 38, in _publish_output_raw
    self._publish(rec)
  File "C:\Users\HEEKWON\anaconda3\envs\reinforcementLearningProject_2\lib\site-packages\wandb\sdk\interface\interface_sock.py", line 39, in _publish
    self._sock_client.send_record_publish(record)
  File "C:\Users\HEEKWON\anaconda3\envs\reinforcementLearningProject_2\lib\site-packages\wandb\sdk\lib\sock_client.py", line 174, in send_record_publish
    self.send_server_request(server_req)
  File "C:\Users\HEEKWON\anaconda3\envs\reinforcementLearningProject_2\lib\site-packages\wandb\sdk\lib\sock_client.py", line 154, in send_server_request
    self._send_message(msg)
  File "C:\Users\HEEKWON\anaconda3\envs\reinforcementLearningProject_2\lib\site-packages\wandb\sdk\lib\sock_client.py", line 151, in _send_message
    self._sendall_with_error_handle(header + data)
  File "C:\Users\HEEKWON\anaconda3\envs\reinforcementLearningProject_2\lib\site-packages\wandb\sdk\lib\sock_client.py", line 130, in _sendall_with_error_handle
    sent = self._sock.send(data)
ConnectionAbortedError: [WinError 10053] 현재 연결은 사용자의 호스트 시스템의 소프트웨어의 의해 중단되었습니다
2025-06-03 17:43:26,467 ERROR   MainThread:25396 [redirect.py:_on_write():664] [no run ID] error in stderr callback
Traceback (most recent call last):
  File "C:\Users\HEEKWON\anaconda3\envs\reinforcementLearningProject_2\lib\site-packages\wandb\sdk\lib\redirect.py", line 662, in _on_write
    cb(written_data)
  File "C:\Users\HEEKWON\anaconda3\envs\reinforcementLearningProject_2\lib\site-packages\wandb\sdk\wandb_run.py", line 2500, in <lambda>
    lambda data: self._console_raw_callback("stderr", data),
  File "C:\Users\HEEKWON\anaconda3\envs\reinforcementLearningProject_2\lib\site-packages\wandb\sdk\wandb_run.py", line 406, in wrapper
    return func(self, *args, **kwargs)
  File "C:\Users\HEEKWON\anaconda3\envs\reinforcementLearningProject_2\lib\site-packages\wandb\sdk\wandb_run.py", line 464, in wrapper_fn
    return func(self, *args, **kwargs)
  File "C:\Users\HEEKWON\anaconda3\envs\reinforcementLearningProject_2\lib\site-packages\wandb\sdk\wandb_run.py", line 1639, in _console_raw_callback
    self._backend.interface.publish_output_raw(name, data)
  File "C:\Users\HEEKWON\anaconda3\envs\reinforcementLearningProject_2\lib\site-packages\wandb\sdk\interface\interface.py", line 762, in publish_output_raw
    self._publish_output_raw(o)
  File "C:\Users\HEEKWON\anaconda3\envs\reinforcementLearningProject_2\lib\site-packages\wandb\sdk\interface\interface_shared.py", line 38, in _publish_output_raw
    self._publish(rec)
  File "C:\Users\HEEKWON\anaconda3\envs\reinforcementLearningProject_2\lib\site-packages\wandb\sdk\interface\interface_sock.py", line 39, in _publish
    self._sock_client.send_record_publish(record)
  File "C:\Users\HEEKWON\anaconda3\envs\reinforcementLearningProject_2\lib\site-packages\wandb\sdk\lib\sock_client.py", line 174, in send_record_publish
    self.send_server_request(server_req)
  File "C:\Users\HEEKWON\anaconda3\envs\reinforcementLearningProject_2\lib\site-packages\wandb\sdk\lib\sock_client.py", line 154, in send_server_request
    self._send_message(msg)
  File "C:\Users\HEEKWON\anaconda3\envs\reinforcementLearningProject_2\lib\site-packages\wandb\sdk\lib\sock_client.py", line 151, in _send_message
    self._sendall_with_error_handle(header + data)
  File "C:\Users\HEEKWON\anaconda3\envs\reinforcementLearningProject_2\lib\site-packages\wandb\sdk\lib\sock_client.py", line 130, in _sendall_with_error_handle
    sent = self._sock.send(data)
ConnectionAbortedError: [WinError 10053] 현재 연결은 사용자의 호스트 시스템의 소프트웨어의 의해 중단되었습니다
2025-06-03 17:43:26,467 ERROR   MainThread:25396 [redirect.py:_on_write():664] [no run ID] error in stderr callback
Traceback (most recent call last):
  File "C:\Users\HEEKWON\anaconda3\envs\reinforcementLearningProject_2\lib\site-packages\wandb\sdk\lib\redirect.py", line 662, in _on_write
    cb(written_data)
  File "C:\Users\HEEKWON\anaconda3\envs\reinforcementLearningProject_2\lib\site-packages\wandb\sdk\wandb_run.py", line 2500, in <lambda>
    lambda data: self._console_raw_callback("stderr", data),
  File "C:\Users\HEEKWON\anaconda3\envs\reinforcementLearningProject_2\lib\site-packages\wandb\sdk\wandb_run.py", line 406, in wrapper
    return func(self, *args, **kwargs)
  File "C:\Users\HEEKWON\anaconda3\envs\reinforcementLearningProject_2\lib\site-packages\wandb\sdk\wandb_run.py", line 464, in wrapper_fn
    return func(self, *args, **kwargs)
  File "C:\Users\HEEKWON\anaconda3\envs\reinforcementLearningProject_2\lib\site-packages\wandb\sdk\wandb_run.py", line 1639, in _console_raw_callback
    self._backend.interface.publish_output_raw(name, data)
  File "C:\Users\HEEKWON\anaconda3\envs\reinforcementLearningProject_2\lib\site-packages\wandb\sdk\interface\interface.py", line 762, in publish_output_raw
    self._publish_output_raw(o)
  File "C:\Users\HEEKWON\anaconda3\envs\reinforcementLearningProject_2\lib\site-packages\wandb\sdk\interface\interface_shared.py", line 38, in _publish_output_raw
    self._publish(rec)
  File "C:\Users\HEEKWON\anaconda3\envs\reinforcementLearningProject_2\lib\site-packages\wandb\sdk\interface\interface_sock.py", line 39, in _publish
    self._sock_client.send_record_publish(record)
  File "C:\Users\HEEKWON\anaconda3\envs\reinforcementLearningProject_2\lib\site-packages\wandb\sdk\lib\sock_client.py", line 174, in send_record_publish
    self.send_server_request(server_req)
  File "C:\Users\HEEKWON\anaconda3\envs\reinforcementLearningProject_2\lib\site-packages\wandb\sdk\lib\sock_client.py", line 154, in send_server_request
    self._send_message(msg)
  File "C:\Users\HEEKWON\anaconda3\envs\reinforcementLearningProject_2\lib\site-packages\wandb\sdk\lib\sock_client.py", line 151, in _send_message
    self._sendall_with_error_handle(header + data)
  File "C:\Users\HEEKWON\anaconda3\envs\reinforcementLearningProject_2\lib\site-packages\wandb\sdk\lib\sock_client.py", line 130, in _sendall_with_error_handle
    sent = self._sock.send(data)
ConnectionAbortedError: [WinError 10053] 현재 연결은 사용자의 호스트 시스템의 소프트웨어의 의해 중단되었습니다
